2022-12-10 09:05:24,381 INFO: Microblog startup [in /Users/dyue/Dropbox/Projects/WebDevelopment/microblog/app/__init__.py:44]
2022-12-10 09:06:20,083 INFO: Microblog startup [in /Users/dyue/Dropbox/Projects/WebDevelopment/microblog/app/__init__.py:44]
2022-12-10 09:11:26,826 INFO: Microblog startup [in /Users/dyue/Dropbox/Projects/WebDevelopment/microblog/app/__init__.py:44]
2022-12-10 09:11:32,633 INFO: Microblog startup [in /Users/dyue/Dropbox/Projects/WebDevelopment/microblog/app/__init__.py:44]
2022-12-10 09:25:28,148 INFO: Microblog startup [in /Users/dyue/Dropbox/Projects/WebDevelopment/microblog/app/__init__.py:44]
2022-12-10 09:37:40,909 INFO: Microblog startup [in /Users/dyue/Dropbox/Projects/WebDevelopment/microblog/app/__init__.py:44]
2022-12-10 09:37:45,047 ERROR: Exception on /user/Daniel N. Yue [GET] [in /Users/dyue/venvs/microblog/lib/python3.8/site-packages/flask/app.py:1741]
Traceback (most recent call last):
  File "/Users/dyue/venvs/microblog/lib/python3.8/site-packages/flask/app.py", line 2525, in wsgi_app
    response = self.full_dispatch_request()
  File "/Users/dyue/venvs/microblog/lib/python3.8/site-packages/flask/app.py", line 1822, in full_dispatch_request
    rv = self.handle_user_exception(e)
  File "/Users/dyue/venvs/microblog/lib/python3.8/site-packages/flask/app.py", line 1820, in full_dispatch_request
    rv = self.dispatch_request()
  File "/Users/dyue/venvs/microblog/lib/python3.8/site-packages/flask/app.py", line 1796, in dispatch_request
    return self.ensure_sync(self.view_functions[rule.endpoint])(**view_args)
  File "/Users/dyue/venvs/microblog/lib/python3.8/site-packages/flask_login/utils.py", line 290, in decorated_view
    return current_app.ensure_sync(func)(*args, **kwargs)
  File "/Users/dyue/Dropbox/Projects/WebDevelopment/microblog/app/routes.py", line 78, in user
    form = EmptyForm()
NameError: name 'EmptyForm' is not defined
2022-12-10 09:38:33,975 INFO: Microblog startup [in /Users/dyue/Dropbox/Projects/WebDevelopment/microblog/app/__init__.py:44]
2022-12-10 09:38:54,470 ERROR: Exception on /user/joyli24 [GET] [in /Users/dyue/venvs/microblog/lib/python3.8/site-packages/flask/app.py:1741]
Traceback (most recent call last):
  File "/Users/dyue/venvs/microblog/lib/python3.8/site-packages/flask/app.py", line 2525, in wsgi_app
    response = self.full_dispatch_request()
  File "/Users/dyue/venvs/microblog/lib/python3.8/site-packages/flask/app.py", line 1822, in full_dispatch_request
    rv = self.handle_user_exception(e)
  File "/Users/dyue/venvs/microblog/lib/python3.8/site-packages/flask/app.py", line 1820, in full_dispatch_request
    rv = self.dispatch_request()
  File "/Users/dyue/venvs/microblog/lib/python3.8/site-packages/flask/app.py", line 1796, in dispatch_request
    return self.ensure_sync(self.view_functions[rule.endpoint])(**view_args)
  File "/Users/dyue/venvs/microblog/lib/python3.8/site-packages/flask_login/utils.py", line 290, in decorated_view
    return current_app.ensure_sync(func)(*args, **kwargs)
  File "/Users/dyue/Dropbox/Projects/WebDevelopment/microblog/app/routes.py", line 79, in user
    return render_template('user.html', user=user, posts=posts, form=form)
  File "/Users/dyue/venvs/microblog/lib/python3.8/site-packages/flask/templating.py", line 147, in render_template
    return _render(app, template, context)
  File "/Users/dyue/venvs/microblog/lib/python3.8/site-packages/flask/templating.py", line 130, in _render
    rv = template.render(context)
  File "/Users/dyue/venvs/microblog/lib/python3.8/site-packages/jinja2/environment.py", line 1301, in render
    self.environment.handle_exception()
  File "/Users/dyue/venvs/microblog/lib/python3.8/site-packages/jinja2/environment.py", line 936, in handle_exception
    raise rewrite_traceback_stack(source=source)
  File "/Users/dyue/Dropbox/Projects/WebDevelopment/microblog/app/templates/user.html", line 1, in top-level template code
    {% extends "base.html" %}
  File "/Users/dyue/Dropbox/Projects/WebDevelopment/microblog/app/templates/base.html", line 31, in top-level template code
    {% block content %}{% endblock %}
  File "/Users/dyue/Dropbox/Projects/WebDevelopment/microblog/app/templates/user.html", line 16, in block 'content'
    <form action="{{ url_for('follow', username=user.username) }}" method="post">
  File "/Users/dyue/venvs/microblog/lib/python3.8/site-packages/flask/app.py", line 2031, in url_for
    return self.handle_url_build_error(error, endpoint, values)
  File "/Users/dyue/venvs/microblog/lib/python3.8/site-packages/flask/app.py", line 2020, in url_for
    rv = url_adapter.build(  # type: ignore[union-attr]
  File "/Users/dyue/venvs/microblog/lib/python3.8/site-packages/werkzeug/routing/map.py", line 917, in build
    raise BuildError(endpoint, values, method, self)
werkzeug.routing.exceptions.BuildError: Could not build url for endpoint 'follow' with values ['username']. Did you mean 'unfollow' instead?
2022-12-10 09:39:21,202 INFO: Microblog startup [in /Users/dyue/Dropbox/Projects/WebDevelopment/microblog/app/__init__.py:44]
